Workbook

Sheet Form Responses 1
A1: Timestamp | B1: 1. আপনার Easy-bike/E-rickshaw-এ বর্তমানে কোন ধরনের ব্যাটারি ব্যবহার করছেন? | C1: 2. আপনার বর্তমান ব্যাটারি সেটটি কিনতে কত টাকা খরচ হয়েছিল? | D1: আপনার ব্যাটারি সেটে মোট কতটি ব্যাটারি আছে এবং প্রতিটি ব্যাটারির ভোল্টেজ/ক্যাপাসিটি কত? ব্যাটারির সংখ্যা: ______ টি ভোল্টেজ (V): ______ ক্যাপাসিটি (Ah): ______ | E1: আপনি প্রতিদিন গড়ে কত কিলোমিটার Easy-bike/E-rickshaw চালান? | F1: সাধারণত প্রতিদিন কয়বার ব্যাটারি চার্জ করেন? | G1: একবার সম্পূর্ণ চার্জ করতে আনুমানিক কত টাকা খরচ হয়? | H1: আপনার বর্তমান ব্যাটারি সেটটি কতদিন (মাস) ধরে ব্যবহার করছেন? | I1: সাধারণত নতুন ব্যাটারি সেট কতদিন ব্যবহার করার পর পরিবর্তন করতে হয়? | J1: ৯. আপনার ব্যাটারি বর্তমানে সবচেয়ে বেশি কোন সমস্যায় পড়ছে? | K1: ১০. পুরোনো ব্যাটারি পরিবর্তনের সময় বিক্রি করলে আনুমানিক কত টাকা পাওয়া যায়?
A2: 46303.033 | B2: Lead-acid | C2: ২৬০০০ | D2: ৬ টি ব্যাটারি, ৭২ ভোল্ট , ৩০ আম্পিয়ার | E2: 61–80 km | F2: ১ বার | G2: 25 | H2: 3 | I2: ১–২ বছর | J2: চার্জ হতে বেশি সময় লাগে | K2: Pray অর্ধেক
A3: 46308.837 | B3: Lead-acid | C3: 75000 | D3: 5, 12v, 160ah | E3: 100 km-এর বেশি | F3: ১ বার | G3: 120tk | H3: 1 month | I3: ১–২ বছর | J3: চার্জ হতে বেশি সময় লাগে | K3: 35000
A4: 46312.726 | B4: Lead-acid | C4: 29500 | D4: 4, 12v, 120AH | E4: 41–60 km | F4: ১ বার | G4: জানা নেই | H4: ২৪ মাস | I4: ২–৩ বছর | J4: চার্জার গরম হয় | K4: 11500
A5: 46312.727 | B5: Lead-acid | C5: 27500 | D5: 4,12v, 180AH | E5: 100 km-এর বেশি | F5: ১ বার | G5: জানা নেই | H5: ১০মাস | I5: ১–২ বছর | J5: চার্জ হতে বেশি সময় লাগে | K5: ১১৫০০
A6: 46312.737 | B6: Lead-acid | C6: 28500 | D6: 4, 12v, 120AH | E6: 61–80 km | F6: ২ বার | G6: ১০টাকা | H6: ৭মাস | I6: ১–২ বছর | J6: দ্রুত চার্জ শেষ হয়ে যায় | K6: 13700
A7: 46314.341 | B7: Lithium (LFP) | C7: 90k | D7: 4 ti 48 voltage | E7: 61–80 km | F7: ১ বার | G7: 60-70 taka | H7: 2-3 years | I7: notun kine use korsi. ekhono replace korini | J7: আগের তুলনায় কম দূরত্ব চলে | K7: 3k-4k
A8: 46321.011 | B8: Lithium (LFP) | C8: 100k | D8: 4 ti | E8: 61–80 km | F8: ১ বার | G8: 300 taka | H8: 2 year | I8: ২–৩ বছর | J8: আগের তুলনায় কম দূরত্ব চলে | K8: 8-10k
A9: 46322.903 | B9: Lead-acid | C9: 27500 | D9: 4 ti | E9: 41–60 km | F9: ১ বার | G9: 300 taka monthly | H9: 2 years | I9: ২–৩ বছর | J9: আগের তুলনায় কম দূরত্ব চলে | K9: 10000 taka
A10: 46322.904 | B10: Lead-acid | C10: 26000 | D10: battery 4 ti | E10: 41–60 km | F10: ১ বার | G10: 300 taka | H10: 2 years | I10: ২–৩ বছর | J10: আগের তুলনায় কম দূরত্ব চলে | K10: 8k-9k taka
A11: 46322.905 | B11: Lead-acid | C11: 28000 | D11: battery 4 ti | E11: 41–60 km | F11: ১ বার | G11: 300 taka | H11: 2.5 years | I11: ২–৩ বছর | J11: আগের তুলনায় কম দূরত্ব চলে | K11: 10000 taka
A12: 46322.906 | B12: Lead-acid | C12: 26000 | D12: Battery 4 ti | E12: 41–60 km | F12: ১ বার | G12: 300 taka | H12: 1.5 years | I12: ২–৩ বছর | J12: আগের তুলনায় কম দূরত্ব চলে | K12: 11k-12k taka
A13: 46322.907 | B13: Lead-acid | C13: 28000 | D13: battery 4 ti | E13: 61–80 km | F13: ১ বার | G13: 250 -280 taka | H13: 2 years | I13: ২–৩ বছর | J13: আগের তুলনায় কম দূরত্ব চলে | K13: 12000 taka
A14: 46322.908 | B14: Lead-acid | C14: 27500 | D14: battery 6 ti | E14: 41–60 km | F14: ১ বার | G14: 300-320 taka | H14: 1.5 years | I14: ২–৩ বছর | J14: আগের তুলনায় কম দূরত্ব চলে | K14: 10000-12000 taka
A15: 46322.909 | B15: Lead-acid | C15: 26500 | D15: battery 4 ti | E15: 41–60 km | F15: ১ বার | G15: 300 taka | H15: 1.5 years | I15: No change | J15: আগের তুলনায় কম দূরত্ব চলে | K15: 9000-10000 taka
A16: 46322.91 | B16: Lead-acid | C16: 26000 | D16: 4 ti | E16: 41–60 km | F16: ১ বার | G16: 300 taka | H16: 2 years | I16: ২–৩ বছর | J16: আগের তুলনায় কম দূরত্ব চলে | K16: 10000 taka
A17: 46322.911 | B17: Lead-acid | C17: 90k | D17: battery 4 ti | E17: 61–80 km | F17: ১ বার | G17: 300 taka | H17: 1.5 years | I17: ২–৩ বছর | J17: আগের তুলনায় কম দূরত্ব চলে | K17: 12000 taka
A18: 46322.914 | B18: Lead-acid | C18: 95k | D18: battery 4 ti | E18: 61–80 km | F18: ১ বার | G18: 300 taka | H18: 2 years | I18: ২–৩ বছর | J18: আগের তুলনায় কম দূরত্ব চলে | K18: 10000-12000 taka
A19: 46313 | B19: Lead-acid | C19: 40K | D19: 5ti | E19: 130km | F19: 1 ber | G19: 150Tk | H19: 6 month | I19: 1-1.5 year | J19: আগের তুলনায় কম দূরত্ব চলে | K19: 30K
A20: 46314 | B20: Lead-acid | C20: 36K | D20: 5ti | E20: 120Km | F20: 1 ber | G20: jane nah | H20: 6month | I20: 6-10 month | J20: চার্জ কম হয় | K20: 35K
A21: 46315 | B21: Lithium (LFP) | C21: 112K(80Kg) | D21: 1ti | E21: 150Km | F21: 1 ber | G21: 10 unit | H21: 8 month | I21: 4-5 year | J21: আগের তুলনায় কম দূরত্ব চলে | K21: 15-20K
A22: 46316 | B22: Lead-acid | C22: 75K | D22: 5ti | E22: 130Km | F22: 1 ber | G22: 100Tk | H22: 5 month | I22: 10-12 month | J22: চার্জ কম থাকে | K22: 35K
A23: 46315 | B23: Lead-acid | C23: 65K | D23: 4ti | E23: 70Km | F23: 1ber | G23: 100TK | H23: 17 month | I23: 15-20 month | J23: আগের তুলনায় কম দূরত্ব চলে | K23: 27K
A24: 46317 | B24: Lithium (LFP) | C24: 130K | D24: 1ti | E24: 170km | F24: 1 ber | G24: 60Tk | H24: 6 month | I24: 4-5 year | J24: এখনো সমেস্যা পাইনাই | K24: 25K
A25: 46317 | B25: Lead-acid | C25: 75K | D25: 4ti | E25: 150Km | F25: 1ber | G25: 90Tk | H25: 2 month | I25: 8-12 month | J25: আগের তুলনায় কম দূরত্ব চলে | K25: 15-20K
A26: 46318 | B26: Lead-acid | C26: 45K | D26: 4ti | E26: 120km | F26: 1 ber | G26: 100Tk | H26: 3 month | I26: 12-15 month | J26: আগের তুলনায় কম দূরত্ব চলে | K26: 26-28K
A27: 46318 | B27: Lead-acid | C27: 96K | D27: 6ti | E27: 150Km | F27: 1 ber | G27: 90Tk | H27: 4 month | I27: 12-16 mont | J27: আগের তুলনায় কম দূরত্ব চলে | K27: 48K
A28: 46318 | B28: Powder | C28: 28K | D28: 4ti | E28: 120Km | F28: 1 ber | G28: 40tk | H28: 6 month | I28: 1-2 year | J28: আগের তুলনায় কম দূরত্ব চলে | K28: 15K
A29: 46323 | B29: Powder | C29: 27000 | D29: 4ti | E29: 40-60 | F29: 1 ber | G29: 250 taka/ month | H29: 18 month | I29: 2-3 years | J29: চার্জ হতে বেশি সময় লাগে | K29: 10k
A30: 46323 | B30: Powder | C30: 28500 | D30: 4i | E30: 40-60 | F30: 1 ber | G30: 280taka/month | H30: 24 month | I30: 2-3 years | J30: চার্জ হতে বেশি সময় লাগে | K30: 11k
A31: 46323 | B31: Powder | C31: 26000 | D31: 4ti | E31: 40-60 | F31: 1 ber | G31: 250taka/month | H31: 18 month | I31: 2-3 years | J31: চার্জ হতে বেশি সময় লাগে | K31: 11k
A32: 46323 | B32: Powder | C32: 35500 | D32: 6ti | E32: 60-80km | F32: 1 ber | G32: 300 taka /month | H32: 24 month | I32: 2-2.5 years | J32: চার্জ হতে বেশি সময় লাগে | K32: 15k
A33: 46323 | B33: Lithium (LFP) | C33: 95K | D33: 4ti | E33: 60-80km | F33: 1 ber | G33: 300taka/month | H33: 24 month | I33: 2.5-3 years | J33: আগের তুলনায় কম দূরত্ব চলে | K33: 15k-18k
A34: 46323 | B34: Powder | C34: 28500 | D34: 4ti | E34: 40-60km | F34: 1ber | G34: 250taka/month | H34: 18 month | I34: 2-3 years | J34: আগের তুলনায় কম দূরত্ব চলে | K34: 10k
A35: 46323 | B35: Powder | C35: 27000 | D35: 4ti | E35: 40-60KM | F35: 1 ber | G35: 280taka/month | H35: 24 month | I35: 2-3 years | J35: আগের তুলনায় কম দূরত্ব চলে | K35: 10k
A36: 46323 | B36: Powder | C36: 26500 | D36: 4ti | E36: 40-60KM | F36: 1 ber | G36: 250taka/month | H36: 24 month | I36: 2-3 years | J36: আগের তুলনায় কম দূরত্ব চলে | K36: 9k
A37: 46323 | B37: Powder | C37: 90k | D37: 4ta | E37: 60-80km | F37: 1ber | G37: 300taka/month | H37: 24 month | I37: 2.5-3 years | J37: আগের তুলনায় কম দূরত্ব চলে | K37: 12k
A38: 46323 | B38: Powder | C38: 28500 | D38: 4ta | E38: 40-60 | F38: 1 ber | G38: 250taka/month | H38: 18 month | I38: 2-3 years | J38: আগের তুলনায় কম দূরত্ব চলে | K38: 10k
A39: 46323 | B39: Powder | C39: 36000 | D39: 6ta | E39: 40-60 | F39: 1ber | G39: 280taka/month | H39: 24 month | I39: 2-3 years | J39: আগের তুলনায় কম দূরত্ব চলে | K39: 12k
A40: 46323 | B40: Powder | C40: 36000 | D40: 6ta | E40: 40-60 | F40: 1ber | G40: 300taka/month | H40: 24 month | I40: 2-3 years | J40: আগের তুলনায় কম দূরত্ব চলে | K40: 12k
...

Sheet Cleaned Data
A1: Timestamp | B1: Battery type | C1: Purchase cost (BDT) | D1: No. of batteries | E1: Voltage per battery (V) | F1: Capacity per battery (Ah) | G1: Daily distance min (km) | H1: Daily distance max (km) | I1: Daily distance mid (km) | J1: Charges per day | K1: Charging cost value (BDT) | L1: Charging cost basis | M1: Months in use | N1: Replacement interval min (months) | O1: Replacement interval max (months) | P1: Replacement interval mid (months) | Q1: Main problem | R1: Resale value min (BDT) | S1: Resale value max (BDT) | T1: Resale value mid (BDT) | U1: Resale / purchase ratio | V1: Review notes
A2: 46303.033 | B2: Lead-acid | C2: 26000 | D2: 6 | E2: 12 | F2: 30 | G2: 61 | H2: 80 | I2: =IF(H2="",G2,AVERAGE(G2:H2)) -> 70.5 | J2: 1 | K2: 600 | L2: Per month (stated) | M2: 3 | N2: 12 | O2: 24 | P2: =IF(COUNT(N2:O2)=0,"",AVERAGE(N2:O2)) -> 18 | Q2: Slow charging | R2: 13000 | S2: 13000 | T2: =AVERAGE(R2:S2) -> 13000 | U2: =T2/C2 -> 0.5 | V2: Pack voltage 72 V stated; per-battery value derived (pack ÷ count). Resale "approximately half": taken as 50% of purchase cost (derived).
A3: 46308.837 | B3: Lead-acid | C3: 75000 | D3: 5 | E3: 12 | F3: 160 | G3: 100 | I3: =IF(H3="",G3,AVERAGE(G3:H3)) -> 100 | J3: 1 | K3: 700 | L3: Per month (stated) | M3: 1 | N3: 12 | O3: 24 | P3: =IF(COUNT(N3:O3)=0,"",AVERAGE(N3:O3)) -> 18 | Q3: Slow charging | R3: 35000 | S3: 35000 | T3: =AVERAGE(R3:S3) -> 35000 | U3: =T3/C3 -> 0.46666667 | V3: Daily distance ">100 km": lower bound used. High purchase cost for Lead-acid; verify battery type/capacity.
A4: 46312.726 | B4: Lead-acid | C4: 29500 | D4: 4 | E4: 12 | F4: 120 | G4: 41 | H4: 60 | I4: =IF(H4="",G4,AVERAGE(G4:H4)) -> 50.5 | J4: 1 | L4: Not known | M4: 24 | N4: 24 | O4: 36 | P4: =IF(COUNT(N4:O4)=0,"",AVERAGE(N4:O4)) -> 30 | Q4: Charger overheating | R4: 11500 | S4: 11500 | T4: =AVERAGE(R4:S4) -> 11500 | U4: =T4/C4 -> 0.38983051
A5: 46312.727 | B5: Lead-acid | C5: 27500 | D5: 4 | E5: 12 | F5: 180 | G5: 100 | I5: =IF(H5="",G5,AVERAGE(G5:H5)) -> 100 | J5: 1 | L5: Not known | M5: 10 | N5: 12 | O5: 24 | P5: =IF(COUNT(N5:O5)=0,"",AVERAGE(N5:O5)) -> 18 | Q5: Slow charging | R5: 11500 | S5: 11500 | T5: =AVERAGE(R5:S5) -> 11500 | U5: =T5/C5 -> 0.41818182 | V5: Daily distance ">100 km": lower bound used.
A6: 46312.737 | B6: Lead-acid | C6: 28500 | D6: 4 | E6: 12 | F6: 120 | G6: 61 | H6: 80 | I6: =IF(H6="",G6,AVERAGE(G6:H6)) -> 70.5 | J6: 2 | K6: 300 | L6: Per month (stated) | M6: 7 | N6: 12 | O6: 24 | P6: =IF(COUNT(N6:O6)=0,"",AVERAGE(N6:O6)) -> 18 | Q6: Fast discharge | R6: 13700 | S6: 13700 | T6: =AVERAGE(R6:S6) -> 13700 | U6: =T6/C6 -> 0.48070175
A7: 46314.341 | B7: Lithium (LFP) | C7: 90000 | D7: 4 | E7: 12 | G7: 61 | H7: 80 | I7: =IF(H7="",G7,AVERAGE(G7:H7)) -> 70.5 | J7: 1 | K7: 240 | L7: Per month (stated) | M7: 30 | P7: =IF(COUNT(N7:O7)=0,"",AVERAGE(N7:O7)) | Q7: Reduced range | R7: 3000 | S7: 4000 | T7: =AVERAGE(R7:S7) -> 3500 | U7: =T7/C7 -> 0.038888889 | V7: Pack voltage 48 V stated; per-battery value derived (pack ÷ count). Range given; midpoint used. Range given; midpoint used. Battery new; not yet replaced.
A8: 46321.011 | B8: Lithium (LFP) | C8: 100000 | D8: 4 | E8: 12 | G8: 61 | H8: 80 | I8: =IF(H8="",G8,AVERAGE(G8:H8)) -> 70.5 | J8: 1 | K8: 300 | L8: Per month (stated) | M8: 24 | N8: 24 | O8: 36 | P8: =IF(COUNT(N8:O8)=0,"",AVERAGE(N8:O8)) -> 30 | Q8: Reduced range | R8: 8000 | S8: 10000 | T8: =AVERAGE(R8:S8) -> 9000 | U8: =T8/C8 -> 0.09
A9: 46322.903 | B9: Lead-acid | C9: 27500 | D9: 4 | E9: 12 | G9: 41 | H9: 60 | I9: =IF(H9="",G9,AVERAGE(G9:H9)) -> 50.5 | J9: 1 | K9: 300 | L9: Per month (stated) | M9: 24 | N9: 24 | O9: 36 | P9: =IF(COUNT(N9:O9)=0,"",AVERAGE(N9:O9)) -> 30 | Q9: Reduced range | R9: 10000 | S9: 10000 | T9: =AVERAGE(R9:S9) -> 10000 | U9: =T9/C9 -> 0.36363636
A10: 46322.904 | B10: Lead-acid | C10: 26000 | D10: 4 | E10: 12 | G10: 41 | H10: 60 | I10: =IF(H10="",G10,AVERAGE(G10:H10)) -> 50.5 | J10: 1 | K10: 300 | L10: Per month (stated) | M10: 24 | N10: 24 | O10: 36 | P10: =IF(COUNT(N10:O10)=0,"",AVERAGE(N10:O10)) -> 30 | Q10: Reduced range | R10: 8000 | S10: 9000 | T10: =AVERAGE(R10:S10) -> 8500 | U10: =T10/C10 -> 0.32692308
A11: 46322.905 | B11: Lead-acid | C11: 28000 | D11: 4 | E11: 12 | G11: 41 | H11: 60 | I11: =IF(H11="",G11,AVERAGE(G11:H11)) -> 50.5 | J11: 1 | K11: 300 | L11: Per month (stated) | M11: 30 | N11: 24 | O11: 36 | P11: =IF(COUNT(N11:O11)=0,"",AVERAGE(N11:O11)) -> 30 | Q11: Reduced range | R11: 10000 | S11: 10000 | T11: =AVERAGE(R11:S11) -> 10000 | U11: =T11/C11 -> 0.35714286
A12: 46322.906 | B12: Lead-acid | C12: 26000 | D12: 4 | E12: 12 | G12: 41 | H12: 60 | I12: =IF(H12="",G12,AVERAGE(G12:H12)) -> 50.5 | J12: 1 | K12: 300 | L12: Per month (stated) | M12: 18 | N12: 24 | O12: 36 | P12: =IF(COUNT(N12:O12)=0,"",AVERAGE(N12:O12)) -> 30 | Q12: Reduced range | R12: 11000 | S12: 12000 | T12: =AVERAGE(R12:S12) -> 11500 | U12: =T12/C12 -> 0.44230769
A13: 46322.907 | B13: Lead-acid | C13: 28000 | D13: 4 | E13: 12 | G13: 61 | H13: 80 | I13: =IF(H13="",G13,AVERAGE(G13:H13)) -> 70.5 | J13: 1 | K13: 265 | L13: Per month (stated) | M13: 24 | N13: 24 | O13: 36 | P13: =IF(COUNT(N13:O13)=0,"",AVERAGE(N13:O13)) -> 30 | Q13: Reduced range | R13: 12000 | S13: 12000 | T13: =AVERAGE(R13:S13) -> 12000 | U13: =T13/C13 -> 0.42857143 | V13: Range given; midpoint used.
A14: 46322.908 | B14: Lead-acid | C14: 27500 | D14: 6 | E14: 12 | G14: 41 | H14: 60 | I14: =IF(H14="",G14,AVERAGE(G14:H14)) -> 50.5 | J14: 1 | K14: 310 | L14: Per month (stated) | M14: 18 | N14: 24 | O14: 36 | P14: =IF(COUNT(N14:O14)=0,"",AVERAGE(N14:O14)) -> 30 | Q14: Reduced range | R14: 10000 | S14: 12000 | T14: =AVERAGE(R14:S14) -> 11000 | U14: =T14/C14 -> 0.4 | V14: Range given; midpoint used.
A15: 46322.909 | B15: Lead-acid | C15: 26500 | D15: 4 | E15: 12 | G15: 41 | H15: 60 | I15: =IF(H15="",G15,AVERAGE(G15:H15)) -> 50.5 | J15: 1 | K15: 300 | L15: Per month (stated) | M15: 18 | P15: =IF(COUNT(N15:O15)=0,"",AVERAGE(N15:O15)) | Q15: Reduced range | R15: 9000 | S15: 10000 | T15: =AVERAGE(R15:S15) -> 9500 | U15: =T15/C15 -> 0.35849057 | V15: Replacement interval: "No change" (not usable).
A16: 46322.91 | B16: Lead-acid | C16: 26000 | D16: 4 | E16: 12 | G16: 41 | H16: 60 | I16: =IF(H16="",G16,AVERAGE(G16:H16)) -> 50.5 | J16: 1 | K16: 300 | L16: Per month (stated) | M16: 24 | N16: 24 | O16: 36 | P16: =IF(COUNT(N16:O16)=0,"",AVERAGE(N16:O16)) -> 30 | Q16: Reduced range | R16: 10000 | S16: 10000 | T16: =AVERAGE(R16:S16) -> 10000 | U16: =T16/C16 -> 0.38461538
A17: 46322.911 | B17: Lead-acid | C17: 90000 | D17: 4 | E17: 12 | G17: 61 | H17: 80 | I17: =IF(H17="",G17,AVERAGE(G17:H17)) -> 70.5 | J17: 1 | K17: 300 | L17: Per month (stated) | M17: 18 | N17: 24 | O17: 36 | P17: =IF(COUNT(N17:O17)=0,"",AVERAGE(N17:O17)) -> 30 | Q17: Reduced range | R17: 12000 | S17: 12000 | T17: =AVERAGE(R17:S17) -> 12000 | U17: =T17/C17 -> 0.13333333 | V17: High purchase cost for Lead-acid; verify battery type/capacity.
A18: 46322.914 | B18: Lead-acid | C18: 95000 | D18: 4 | E18: 12 | G18: 61 | H18: 80 | I18: =IF(H18="",G18,AVERAGE(G18:H18)) -> 70.5 | J18: 1 | K18: 300 | L18: Per month (stated) | M18: 24 | N18: 24 | O18: 36 | P18: =IF(COUNT(N18:O18)=0,"",AVERAGE(N18:O18)) -> 30 | Q18: Reduced range | R18: 10000 | S18: 12000 | T18: =AVERAGE(R18:S18) -> 11000 | U18: =T18/C18 -> 0.11578947 | V18: High purchase cost for Lead-acid; verify battery type/capacity.
A19: 46313 | B19: Lead-acid | C19: 40000 | D19: 5 | E19: 12 | G19: 130 | H19: 130 | I19: =IF(H19="",G19,AVERAGE(G19:H19)) -> 130 | J19: 1 | K19: 150 | L19: Per month (stated) | M19: 6 | N19: 12 | O19: 18 | P19: =IF(COUNT(N19:O19)=0,"",AVERAGE(N19:O19)) -> 15 | Q19: Reduced range | R19: 30000 | S19: 30000 | T19: =AVERAGE(R19:S19) -> 30000 | U19: =T19/C19 -> 0.75
A20: 46314 | B20: Lead-acid | C20: 36000 | D20: 5 | E20: 12 | G20: 120 | H20: 120 | I20: =IF(H20="",G20,AVERAGE(G20:H20)) -> 120 | J20: 1 | L20: Not known | M20: 6 | N20: 6 | O20: 10 | P20: =IF(COUNT(N20:O20)=0,"",AVERAGE(N20:O20)) -> 8 | Q20: Low charge / capacity | R20: 35000 | S20: 35000 | T20: =AVERAGE(R20:S20) -> 35000 | U20: =T20/C20 -> 0.97222222
A21: 46315 | B21: Lithium (LFP) | C21: 112000 | D21: 1 | E21: 12 | G21: 150 | H21: 150 | I21: =IF(H21="",G21,AVERAGE(G21:H21)) -> 150 | J21: 1 | K21: 300 | L21: Per month (stated) | M21: 8 | N21: 48 | O21: 60 | P21: =IF(COUNT(N21:O21)=0,"",AVERAGE(N21:O21)) -> 54 | Q21: Reduced range | R21: 15000 | S21: 20000 | T21: =AVERAGE(R21:S21) -> 17500 | U21: =T21/C21 -> 0.15625 | V21: Charging cost given in kWh units, not BDT.
A22: 46316 | B22: Lead-acid | C22: 75000 | D22: 5 | E22: 12 | G22: 130 | H22: 130 | I22: =IF(H22="",G22,AVERAGE(G22:H22)) -> 130 | J22: 1 | K22: 100 | L22: Unspecified | M22: 5 | N22: 10 | O22: 12 | P22: =IF(COUNT(N22:O22)=0,"",AVERAGE(N22:O22)) -> 11 | Q22: Low charge / capacity | R22: 35000 | S22: 35000 | T22: =AVERAGE(R22:S22) -> 35000 | U22: =T22/C22 -> 0.46666667 | V22: High purchase cost for Lead-acid; verify battery type/capacity.
A23: 46315 | B23: Lead-acid | C23: 65000 | D23: 4 | E23: 12 | G23: 70 | H23: 70 | I23: =IF(H23="",G23,AVERAGE(G23:H23)) -> 70 | J23: 1 | K23: 100 | L23: Unspecified | M23: 17 | N23: 15 | O23: 20 | P23: =IF(COUNT(N23:O23)=0,"",AVERAGE(N23:O23)) -> 17.5 | Q23: Reduced range | R23: 27000 | S23: 27000 | T23: =AVERAGE(R23:S23) -> 27000 | U23: =T23/C23 -> 0.41538462 | V23: High purchase cost for Lead-acid; verify battery type/capacity.
A24: 46317 | B24: Lithium (LFP) | C24: 130000 | D24: 1 | E24: 12 | G24: 170 | H24: 170 | I24: =IF(H24="",G24,AVERAGE(G24:H24)) -> 170 | J24: 1 | K24: 180 | L24: Unspecified | M24: 6 | N24: 48 | O24: 60 | P24: =IF(COUNT(N24:O24)=0,"",AVERAGE(N24:O24)) -> 54 | Q24: No problem yet | R24: 25000 | S24: 25000 | T24: =AVERAGE(R24:S24) -> 25000 | U24: =T24/C24 -> 0.19230769
A25: 46317 | B25: Lead-acid | C25: 75000 | D25: 4 | E25: 12 | G25: 150 | H25: 150 | I25: =IF(H25="",G25,AVERAGE(G25:H25)) -> 150 | J25: 1 | K25: 90 | L25: Unspecified | M25: 2 | N25: 8 | O25: 12 | P25: =IF(COUNT(N25:O25)=0,"",AVERAGE(N25:O25)) -> 10 | Q25: Reduced range | R25: 15000 | S25: 20000 | T25: =AVERAGE(R25:S25) -> 17500 | U25: =T25/C25 -> 0.23333333 | V25: High purchase cost for Lead-acid; verify battery type/capacity.
A26: 46318 | B26: Lead-acid | C26: 45000 | D26: 4 | E26: 12 | G26: 120 | H26: 120 | I26: =IF(H26="",G26,AVERAGE(G26:H26)) -> 120 | J26: 1 | K26: 100 | L26: Unspecified | M26: 3 | N26: 12 | O26: 15 | P26: =IF(COUNT(N26:O26)=0,"",AVERAGE(N26:O26)) -> 13.5 | Q26: Reduced range | R26: 26000 | S26: 28000 | T26: =AVERAGE(R26:S26) -> 27000 | U26: =T26/C26 -> 0.6
A27: 46318 | B27: Lead-acid | C27: 96000 | D27: 6 | E27: 12 | G27: 150 | H27: 150 | I27: =IF(H27="",G27,AVERAGE(G27:H27)) -> 150 | J27: 1 | K27: 90 | L27: Unspecified | M27: 4 | N27: 12 | O27: 16 | P27: =IF(COUNT(N27:O27)=0,"",AVERAGE(N27:O27)) -> 14 | Q27: Reduced range | R27: 48000 | S27: 48000 | T27: =AVERAGE(R27:S27) -> 48000 | U27: =T27/C27 -> 0.5 | V27: High purchase cost for Lead-acid; verify battery type/capacity.
A28: 46318 | B28: Powder | C28: 28000 | D28: 4 | E28: 12 | G28: 120 | H28: 120 | I28: =IF(H28="",G28,AVERAGE(G28:H28)) -> 120 | J28: 1 | K28: 1200 | L28: Per month (stated) | M28: 6 | N28: 12 | O28: 24 | P28: =IF(COUNT(N28:O28)=0,"",AVERAGE(N28:O28)) -> 18 | Q28: Reduced range | R28: 15000 | S28: 15000 | T28: =AVERAGE(R28:S28) -> 15000 | U28: =T28/C28 -> 0.53571429
A29: 46323 | B29: Powder | C29: 27000 | D29: 4 | E29: 12 | G29: 40 | H29: 60 | I29: =IF(H29="",G29,AVERAGE(G29:H29)) -> 50 | J29: 1 | K29: 250 | L29: Per month (stated) | M29: 18 | N29: 24 | O29: 36 | P29: =IF(COUNT(N29:O29)=0,"",AVERAGE(N29:O29)) -> 30 | Q29: Slow charging | R29: 10000 | S29: 10000 | T29: =AVERAGE(R29:S29) -> 10000 | U29: =T29/C29 -> 0.37037037
A30: 46323 | B30: Powder | C30: 28500 | D30: 4 | E30: 12 | G30: 40 | H30: 60 | I30: =IF(H30="",G30,AVERAGE(G30:H30)) -> 50 | J30: 1 | K30: 280 | L30: Per month (stated) | M30: 24 | N30: 24 | O30: 36 | P30: =IF(COUNT(N30:O30)=0,"",AVERAGE(N30:O30)) -> 30 | Q30: Slow charging | R30: 11000 | S30: 11000 | T30: =AVERAGE(R30:S30) -> 11000 | U30: =T30/C30 -> 0.38596491
A31: 46323 | B31: Powder | C31: 26000 | D31: 4 | E31: 12 | G31: 40 | H31: 60 | I31: =IF(H31="",G31,AVERAGE(G31:H31)) -> 50 | J31: 1 | K31: 250 | L31: Per month (stated) | M31: 18 | N31: 24 | O31: 36 | P31: =IF(COUNT(N31:O31)=0,"",AVERAGE(N31:O31)) -> 30 | Q31: Slow charging | R31: 11000 | S31: 11000 | T31: =AVERAGE(R31:S31) -> 11000 | U31: =T31/C31 -> 0.42307692
A32: 46323 | B32: Powder | C32: 35500 | D32: 6 | E32: 12 | G32: 60 | H32: 80 | I32: =IF(H32="",G32,AVERAGE(G32:H32)) -> 70 | J32: 1 | K32: 300 | L32: Per month (stated) | M32: 24 | N32: 24 | O32: 30 | P32: =IF(COUNT(N32:O32)=0,"",AVERAGE(N32:O32)) -> 27 | Q32: Slow charging | R32: 15000 | S32: 15000 | T32: =AVERAGE(R32:S32) -> 15000 | U32: =T32/C32 -> 0.42253521
A33: 46323 | B33: Lithium (LFP) | C33: 95000 | D33: 4 | E33: 12 | G33: 60 | H33: 80 | I33: =IF(H33="",G33,AVERAGE(G33:H33)) -> 70 | J33: 1 | K33: 300 | L33: Per month (stated) | M33: 24 | N33: 30 | O33: 36 | P33: =IF(COUNT(N33:O33)=0,"",AVERAGE(N33:O33)) -> 33 | Q33: Reduced range | R33: 15000 | S33: 18000 | T33: =AVERAGE(R33:S33) -> 16500 | U33: =T33/C33 -> 0.17368421
A34: 46323 | B34: Powder | C34: 28500 | D34: 4 | E34: 12 | G34: 40 | H34: 60 | I34: =IF(H34="",G34,AVERAGE(G34:H34)) -> 50 | J34: 1 | K34: 250 | L34: Per month (stated) | M34: 18 | N34: 24 | O34: 36 | P34: =IF(COUNT(N34:O34)=0,"",AVERAGE(N34:O34)) -> 30 | Q34: Reduced range | R34: 10000 | S34: 10000 | T34: =AVERAGE(R34:S34) -> 10000 | U34: =T34/C34 -> 0.35087719
A35: 46323 | B35: Powder | C35: 27000 | D35: 4 | E35: 12 | G35: 40 | H35: 60 | I35: =IF(H35="",G35,AVERAGE(G35:H35)) -> 50 | J35: 1 | K35: 280 | L35: Per month (stated) | M35: 24 | N35: 24 | O35: 36 | P35: =IF(COUNT(N35:O35)=0,"",AVERAGE(N35:O35)) -> 30 | Q35: Reduced range | R35: 10000 | S35: 10000 | T35: =AVERAGE(R35:S35) -> 10000 | U35: =T35/C35 -> 0.37037037
A36: 46323 | B36: Powder | C36: 26500 | D36: 4 | E36: 12 | G36: 40 | H36: 60 | I36: =IF(H36="",G36,AVERAGE(G36:H36)) -> 50 | J36: 1 | K36: 250 | L36: Per month (stated) | M36: 24 | N36: 24 | O36: 36 | P36: =IF(COUNT(N36:O36)=0,"",AVERAGE(N36:O36)) -> 30 | Q36: Reduced range | R36: 9000 | S36: 9000 | T36: =AVERAGE(R36:S36) -> 9000 | U36: =T36/C36 -> 0.33962264
A37: 46323 | B37: Powder | C37: 90000 | D37: 4 | E37: 12 | G37: 60 | H37: 80 | I37: =IF(H37="",G37,AVERAGE(G37:H37)) -> 70 | J37: 1 | K37: 300 | L37: Per month (stated) | M37: 24 | N37: 30 | O37: 36 | P37: =IF(COUNT(N37:O37)=0,"",AVERAGE(N37:O37)) -> 33 | Q37: Reduced range | R37: 12000 | S37: 12000 | T37: =AVERAGE(R37:S37) -> 12000 | U37: =T37/C37 -> 0.13333333 | V37: High purchase cost for Powder; verify battery type/capacity.
A38: 46323 | B38: Powder | C38: 28500 | D38: 4 | E38: 12 | G38: 40 | H38: 60 | I38: =IF(H38="",G38,AVERAGE(G38:H38)) -> 50 | J38: 1 | K38: 250 | L38: Per month (stated) | M38: 18 | N38: 24 | O38: 36 | P38: =IF(COUNT(N38:O38)=0,"",AVERAGE(N38:O38)) -> 30 | Q38: Reduced range | R38: 10000 | S38: 10000 | T38: =AVERAGE(R38:S38) -> 10000 | U38: =T38/C38 -> 0.35087719
A39: 46323 | B39: Powder | C39: 36000 | D39: 6 | E39: 12 | G39: 40 | H39: 60 | I39: =IF(H39="",G39,AVERAGE(G39:H39)) -> 50 | J39: 1 | K39: 280 | L39: Per month (stated) | M39: 24 | N39: 24 | O39: 36 | P39: =IF(COUNT(N39:O39)=0,"",AVERAGE(N39:O39)) -> 30 | Q39: Reduced range | R39: 12000 | S39: 12000 | T39: =AVERAGE(R39:S39) -> 12000 | U39: =T39/C39 -> 0.33333333
A40: 46323 | B40: Powder | C40: 36000 | D40: 6 | E40: 12 | G40: 40 | H40: 60 | I40: =IF(H40="",G40,AVERAGE(G40:H40)) -> 50 | J40: 1 | K40: 300 | L40: Per month (stated) | M40: 24 | N40: 24 | O40: 36 | P40: =IF(COUNT(N40:O40)=0,"",AVERAGE(N40:O40)) -> 30 | Q40: Reduced range | R40: 12000 | S40: 12000 | T40: =AVERAGE(R40:S40) -> 12000 | U40: =T40/C40 -> 0.33333333
...

Sheet Summary
A1: Easy-Bike / E-Rickshaw Battery Field Survey – Summary (Khulna region, Oct 2026)
A2: All figures are live formulas on the "Cleaned Data" sheet. Means exclude blanks (non-responses).
A4: 1. Sample by battery type
A5: Battery type | B5: Responses (n) | C5: Share of sample
A6: Lead-acid | B6: =COUNTIF('Cleaned Data'!$B$2:$B$44,A6) -> 22 | C6: =B6/B$9 -> 0.51162791
A7: Lithium (LFP) | B7: =COUNTIF('Cleaned Data'!$B$2:$B$44,A7) -> 5 | C7: =B7/B$9 -> 0.11627907
A8: Powder | B8: =COUNTIF('Cleaned Data'!$B$2:$B$44,A8) -> 16 | C8: =B8/B$9 -> 0.37209302
A9: Total | B9: =SUM(B6:B8) -> 43 | C9: =SUM(C6:C8) -> 1
A11: 2. Key indicators by battery type (mean)
A12: Indicator | B12: Lead-acid | C12: Lithium (LFP) | D12: Powder | E12: All
A13: Purchase cost (BDT) | B13: =IFERROR(AVERAGEIFS('Cleaned Data'!$C$2:$C$44,'Cleaned Data'!$B$2:$B$44,B$12),"") -> 46318.182 | C13: =IFERROR(AVERAGEIFS('Cleaned Data'!$C$2:$C$44,'Cleaned Data'!$B$2:$B$44,C$12),"") -> 105400 | D13: =IFERROR(AVERAGEIFS('Cleaned Data'!$C$2:$C$44,'Cleaned Data'!$B$2:$B$44,D$12),"") -> 32906.25 | E13: =AVERAGE('Cleaned Data'!$C$2:$C$44) -> 48197.674
A14: Purchase cost excl. rows flagged "High purchase cost" (BDT) | B14: =IFERROR(AVERAGEIFS('Cleaned Data'!$C$2:$C$44,'Cleaned Data'!$B$2:$B$44,B$12,'Cleaned Data'!$V$2:$V$44,"<>*High purchase cost*"),"") -> 29866.667 | C14: =IFERROR(AVERAGEIFS('Cleaned Data'!$C$2:$C$44,'Cleaned Data'!$B$2:$B$44,C$12,'Cleaned Data'!$V$2:$V$44,"<>*High purchase cost*"),"") -> 105400 | D14: =IFERROR(AVERAGEIFS('Cleaned Data'!$C$2:$C$44,'Cleaned Data'!$B$2:$B$44,D$12,'Cleaned Data'!$V$2:$V$44,"<>*High purchase cost*"),"") -> 29100 | E14: =AVERAGEIFS('Cleaned Data'!$C$2:$C$44,'Cleaned Data'!$V$2:$V$44,"<>*High purchase cost*") -> 40328.571
A15: Min purchase cost (BDT) | B15: =_xlfn.MINIFS('Cleaned Data'!$C$2:$C$44,'Cleaned Data'!$B$2:$B$44,B$12) -> #NAME? | C15: =_xlfn.MINIFS('Cleaned Data'!$C$2:$C$44,'Cleaned Data'!$B$2:$B$44,C$12) -> #NAME? | D15: =_xlfn.MINIFS('Cleaned Data'!$C$2:$C$44,'Cleaned Data'!$B$2:$B$44,D$12) -> #NAME? | E15: =MIN('Cleaned Data'!$C$2:$C$44) -> 26000
A16: Max purchase cost (BDT) | B16: =_xlfn.MAXIFS('Cleaned Data'!$C$2:$C$44,'Cleaned Data'!$B$2:$B$44,B$12) -> #NAME? | C16: =_xlfn.MAXIFS('Cleaned Data'!$C$2:$C$44,'Cleaned Data'!$B$2:$B$44,C$12) -> #NAME? | D16: =_xlfn.MAXIFS('Cleaned Data'!$C$2:$C$44,'Cleaned Data'!$B$2:$B$44,D$12) -> #NAME? | E16: =MAX('Cleaned Data'!$C$2:$C$44) -> 130000
A17: No. of batteries per set | B17: =IFERROR(AVERAGEIFS('Cleaned Data'!$D$2:$D$44,'Cleaned Data'!$B$2:$B$44,B$12),"") -> 4.4545455 | C17: =IFERROR(AVERAGEIFS('Cleaned Data'!$D$2:$D$44,'Cleaned Data'!$B$2:$B$44,C$12),"") -> 2.8 | D17: =IFERROR(AVERAGEIFS('Cleaned Data'!$D$2:$D$44,'Cleaned Data'!$B$2:$B$44,D$12),"") -> 4.375 | E17: =AVERAGE('Cleaned Data'!$D$2:$D$44) -> 4.2325581
A18: Daily distance, mid (km) | B18: =IFERROR(AVERAGEIFS('Cleaned Data'!$I$2:$I$44,'Cleaned Data'!$B$2:$B$44,B$12),"") -> 83.022727 | C18: =IFERROR(AVERAGEIFS('Cleaned Data'!$I$2:$I$44,'Cleaned Data'!$B$2:$B$44,C$12),"") -> 106.2 | D18: =IFERROR(AVERAGEIFS('Cleaned Data'!$I$2:$I$44,'Cleaned Data'!$B$2:$B$44,D$12),"") -> 56.875 | E18: =AVERAGE('Cleaned Data'!$I$2:$I$44) -> 75.988372
A19: Charges per day | B19: =IFERROR(AVERAGEIFS('Cleaned Data'!$J$2:$J$44,'Cleaned Data'!$B$2:$B$44,B$12),"") -> 1.0454545 | C19: =IFERROR(AVERAGEIFS('Cleaned Data'!$J$2:$J$44,'Cleaned Data'!$B$2:$B$44,C$12),"") -> 1 | D19: =IFERROR(AVERAGEIFS('Cleaned Data'!$J$2:$J$44,'Cleaned Data'!$B$2:$B$44,D$12),"") -> 1 | E19: =AVERAGE('Cleaned Data'!$J$2:$J$44) -> 1.0232558
A20: Months in use (current set) | B20: =IFERROR(AVERAGEIFS('Cleaned Data'!$M$2:$M$44,'Cleaned Data'!$B$2:$B$44,B$12),"") -> 14.090909 | C20: =IFERROR(AVERAGEIFS('Cleaned Data'!$M$2:$M$44,'Cleaned Data'!$B$2:$B$44,C$12),"") -> 18.4 | D20: =IFERROR(AVERAGEIFS('Cleaned Data'!$M$2:$M$44,'Cleaned Data'!$B$2:$B$44,D$12),"") -> 21 | E20: =AVERAGE('Cleaned Data'!$M$2:$M$44) -> 17.162791
A21: Replacement interval, mid (months) | B21: =IFERROR(AVERAGEIFS('Cleaned Data'!$P$2:$P$44,'Cleaned Data'!$B$2:$B$44,B$12),"") -> 21.952381 | C21: =IFERROR(AVERAGEIFS('Cleaned Data'!$P$2:$P$44,'Cleaned Data'!$B$2:$B$44,C$12),"") -> 42.75 | D21: =IFERROR(AVERAGEIFS('Cleaned Data'!$P$2:$P$44,'Cleaned Data'!$B$2:$B$44,D$12),"") -> 29.25 | E21: =AVERAGE('Cleaned Data'!$P$2:$P$44) -> 26.829268
A22: Resale value, mid (BDT) | B22: =IFERROR(AVERAGEIFS('Cleaned Data'!$T$2:$T$44,'Cleaned Data'!$B$2:$B$44,B$12),"") -> 18622.727 | C22: =IFERROR(AVERAGEIFS('Cleaned Data'!$T$2:$T$44,'Cleaned Data'!$B$2:$B$44,C$12),"") -> 14300 | D22: =IFERROR(AVERAGEIFS('Cleaned Data'!$T$2:$T$44,'Cleaned Data'!$B$2:$B$44,D$12),"") -> 11062.5 | E22: =AVERAGE('Cleaned Data'!$T$2:$T$44) -> 15306.977
A23: Resale / purchase ratio (mean of ratios) | B23: =IFERROR(AVERAGEIFS('Cleaned Data'!$U$2:$U$44,'Cleaned Data'!$B$2:$B$44,B$12),"") -> 0.43199081 | C23: =IFERROR(AVERAGEIFS('Cleaned Data'!$U$2:$U$44,'Cleaned Data'!$B$2:$B$44,C$12),"") -> 0.13022616 | D23: =IFERROR(AVERAGEIFS('Cleaned Data'!$U$2:$U$44,'Cleaned Data'!$B$2:$B$44,D$12),"") -> 0.36361982 | E23: =AVERAGE('Cleaned Data'!$U$2:$U$44) -> 0.37146153
A25: 3. Main problem reported (count of responses)
A26: Problem | B26: Lead-acid | C26: Lithium (LFP) | D26: Powder | E26: All | F26: % of all
A27: Reduced range | B27: =COUNTIFS('Cleaned Data'!$Q$2:$Q$44,$A27,'Cleaned Data'!$B$2:$B$44,B$26) -> 15 | C27: =COUNTIFS('Cleaned Data'!$Q$2:$Q$44,$A27,'Cleaned Data'!$B$2:$B$44,C$26) -> 4 | D27: =COUNTIFS('Cleaned Data'!$Q$2:$Q$44,$A27,'Cleaned Data'!$B$2:$B$44,D$26) -> 12 | E27: =SUM(B27:D27) -> 31 | F27: =E27/E$33 -> 0.72093023
A28: Slow charging | B28: =COUNTIFS('Cleaned Data'!$Q$2:$Q$44,$A28,'Cleaned Data'!$B$2:$B$44,B$26) -> 3 | C28: =COUNTIFS('Cleaned Data'!$Q$2:$Q$44,$A28,'Cleaned Data'!$B$2:$B$44,C$26) -> 0 | D28: =COUNTIFS('Cleaned Data'!$Q$2:$Q$44,$A28,'Cleaned Data'!$B$2:$B$44,D$26) -> 4 | E28: =SUM(B28:D28) -> 7 | F28: =E28/E$33 -> 0.1627907
A29: Charger overheating | B29: =COUNTIFS('Cleaned Data'!$Q$2:$Q$44,$A29,'Cleaned Data'!$B$2:$B$44,B$26) -> 1 | C29: =COUNTIFS('Cleaned Data'!$Q$2:$Q$44,$A29,'Cleaned Data'!$B$2:$B$44,C$26) -> 0 | D29: =COUNTIFS('Cleaned Data'!$Q$2:$Q$44,$A29,'Cleaned Data'!$B$2:$B$44,D$26) -> 0 | E29: =SUM(B29:D29) -> 1 | F29: =E29/E$33 -> 0.023255814
A30: Fast discharge | B30: =COUNTIFS('Cleaned Data'!$Q$2:$Q$44,$A30,'Cleaned Data'!$B$2:$B$44,B$26) -> 1 | C30: =COUNTIFS('Cleaned Data'!$Q$2:$Q$44,$A30,'Cleaned Data'!$B$2:$B$44,C$26) -> 0 | D30: =COUNTIFS('Cleaned Data'!$Q$2:$Q$44,$A30,'Cleaned Data'!$B$2:$B$44,D$26) -> 0 | E30: =SUM(B30:D30) -> 1 | F30: =E30/E$33 -> 0.023255814
A31: Low charge / capacity | B31: =COUNTIFS('Cleaned Data'!$Q$2:$Q$44,$A31,'Cleaned Data'!$B$2:$B$44,B$26) -> 2 | C31: =COUNTIFS('Cleaned Data'!$Q$2:$Q$44,$A31,'Cleaned Data'!$B$2:$B$44,C$26) -> 0 | D31: =COUNTIFS('Cleaned Data'!$Q$2:$Q$44,$A31,'Cleaned Data'!$B$2:$B$44,D$26) -> 0 | E31: =SUM(B31:D31) -> 2 | F31: =E31/E$33 -> 0.046511628
A32: No problem yet | B32: =COUNTIFS('Cleaned Data'!$Q$2:$Q$44,$A32,'Cleaned Data'!$B$2:$B$44,B$26) -> 0 | C32: =COUNTIFS('Cleaned Data'!$Q$2:$Q$44,$A32,'Cleaned Data'!$B$2:$B$44,C$26) -> 1 | D32: =COUNTIFS('Cleaned Data'!$Q$2:$Q$44,$A32,'Cleaned Data'!$B$2:$B$44,D$26) -> 0 | E32: =SUM(B32:D32) -> 1 | F32: =E32/E$33 -> 0.023255814
A33: Total | B33: =SUM(B27:B32) -> 22 | C33: =SUM(C27:C32) -> 5 | D33: =SUM(D27:D32) -> 16 | E33: =SUM(E27:E32) -> 43
A35: 4. Charging cost – only where basis is stated (BDT)
A36: Basis | B36: n | C36: Mean (BDT) | D36: Min (BDT) | E36: Max (BDT)
A37: Per month (stated) | B37: =COUNTIF('Cleaned Data'!$L$2:$L$44,$A37) -> 34 | C37: =IFERROR(AVERAGEIFS('Cleaned Data'!$K$2:$K$44,'Cleaned Data'!$L$2:$L$44,$A37),"") -> 327.5 | D37: =_xlfn.MINIFS('Cleaned Data'!$K$2:$K$44,'Cleaned Data'!$L$2:$L$44,$A37) -> #NAME? | E37: =_xlfn.MAXIFS('Cleaned Data'!$K$2:$K$44,'Cleaned Data'!$L$2:$L$44,$A37) -> #NAME?
A38: Unspecified | B38: =COUNTIF('Cleaned Data'!$L$2:$L$44,$A38) -> 6 | C38: =IFERROR(AVERAGEIFS('Cleaned Data'!$K$2:$K$44,'Cleaned Data'!$L$2:$L$44,$A38),"") -> 110 | D38: =_xlfn.MINIFS('Cleaned Data'!$K$2:$K$44,'Cleaned Data'!$L$2:$L$44,$A38) -> #NAME? | E38: =_xlfn.MAXIFS('Cleaned Data'!$K$2:$K$44,'Cleaned Data'!$L$2:$L$44,$A38) -> #NAME?
A39: kWh units | B39: =COUNTIF('Cleaned Data'!$L$2:$L$44,$A39) -> 0 | C39: =IFERROR(AVERAGEIFS('Cleaned Data'!$K$2:$K$44,'Cleaned Data'!$L$2:$L$44,$A39),"") | D39: =_xlfn.MINIFS('Cleaned Data'!$K$2:$K$44,'Cleaned Data'!$L$2:$L$44,$A39) -> #NAME? | E39: =_xlfn.MAXIFS('Cleaned Data'!$K$2:$K$44,'Cleaned Data'!$L$2:$L$44,$A39) -> #NAME?
A40: Not known | B40: =COUNTIF('Cleaned Data'!$L$2:$L$44,$A40) -> 3
A42: 5. Cleaning rules & assumptions
A43: 1. Original sheet "Form Responses 1" is unchanged; all standardisation is on "Cleaned Data".
A44: 2. Bengali digits converted to Western digits; "k" suffix = ×1000 (e.g. 90k = 90,000 BDT).
A45: 3. Ranges are stored as min and max; the mid column is the average. Single values have min = max.
...
